Workbook
Name ServiceTypes: 'Settings'!B12:B19
Name LeadSources: 'Settings'!B21:B25
Name LeadStatuses: 'Settings'!B27:B33
Name JobStatuses: 'Settings'!B35:B40
Name PaymentMethods: 'Settings'!B42:B46

Sheet Settings
A1: COMPANY INFO
A2: Company Name | B2: Hammer Brick & Home LLC
A3: HIC License # | B3: 2131291
A4: Business Phone
A5: Business Email
A6: Business Address
A7: Default Tax Rate (e.g., 0.08875) | B7: 0
A8: Default Deposit % (0-1) | B8: 0.2
A9: Default Payment Terms | B9: Net 15
A11: LISTS (Edit below to customize dropdowns)
A12: Service Types | B12: Masonry
B13: Landscaping
B14: Remodeling - Kitchen
B15: Remodeling - Bath
B16: Power Washing
B17: Tile & Flooring
B18: Concrete / Pavers
B19: Painting
A21: Lead Sources | B21: Google
B22: Instagram
B23: Facebook
B24: Referral
B25: Yard Sign
A27: Lead Statuses | B27: New
B28: Contacted
B29: Scheduled
B30: Estimate Sent
B31: Won
B32: Lost
B33: Do Not Contact
A35: Job Statuses | B35: Planned
B36: Scheduled
B37: In Progress
B38: Inspection
B39: Complete
B40: On Hold
A42: Payment Methods | B42: Cash
B43: Check
B44: Credit Card
B45: ACH
...

Sheet CRM_Leads
A1: Lead ID | B1: Date | C1: Client Name | D1: Phone | E1: Email | F1: Address | G1: City | H1: ZIP | I1: Service Type | J1: Source | K1: Status | L1: Assigned To | M1: Follow-Up Date | N1: Budget ($) | O1: Notes
A2: =IF(C2="","",CONCAT("LDR-",TEXT(ROW()-1,"0000")))
A3: =IF(C3="","",CONCAT("LDR-",TEXT(ROW()-1,"0000")))
A4: =IF(C4="","",CONCAT("LDR-",TEXT(ROW()-1,"0000")))
A5: =IF(C5="","",CONCAT("LDR-",TEXT(ROW()-1,"0000")))
A6: =IF(C6="","",CONCAT("LDR-",TEXT(ROW()-1,"0000")))
A7: =IF(C7="","",CONCAT("LDR-",TEXT(ROW()-1,"0000")))
A8: =IF(C8="","",CONCAT("LDR-",TEXT(ROW()-1,"0000")))
A9: =IF(C9="","",CONCAT("LDR-",TEXT(ROW()-1,"0000")))
A10: =IF(C10="","",CONCAT("LDR-",TEXT(ROW()-1,"0000")))
A11: =IF(C11="","",CONCAT("LDR-",TEXT(ROW()-1,"0000")))
A12: =IF(C12="","",CONCAT("LDR-",TEXT(ROW()-1,"0000")))
A13: =IF(C13="","",CONCAT("LDR-",TEXT(ROW()-1,"0000")))
... A501: =IF(C501="","",CONCAT("LDR-",TEXT(ROW()-1,"0000")))

Sheet Project_Tracker
A1: Project ID | B1: Lead ID | C1: Client Name | D1: Service Type | E1: Job Status | F1: Start Date | G1: Target Finish | H1: Actual Finish | I1: Street | J1: City | K1: ZIP | L1: Estimator | M1: Crew Lead | N1: Budget ($) | O1: Actual Cost ($) | P1: Variance ($) | Q1: Drive Folder Link | R1: Notes
A2: =IF(C2="","",CONCAT("JOB-",TEXT(ROW()-1,"0000"))) | P2: =N(O2)-N(N2)
A3: =IF(C3="","",CONCAT("JOB-",TEXT(ROW()-1,"0000"))) | P3: =N(O3)-N(N3)
A4: =IF(C4="","",CONCAT("JOB-",TEXT(ROW()-1,"0000"))) | P4: =N(O4)-N(N4)
A5: =IF(C5="","",CONCAT("JOB-",TEXT(ROW()-1,"0000"))) | P5: =N(O5)-N(N5)
A6: =IF(C6="","",CONCAT("JOB-",TEXT(ROW()-1,"0000"))) | P6: =N(O6)-N(N6)
A7: =IF(C7="","",CONCAT("JOB-",TEXT(ROW()-1,"0000"))) | P7: =N(O7)-N(N7)
A8: =IF(C8="","",CONCAT("JOB-",TEXT(ROW()-1,"0000"))) | P8: =N(O8)-N(N8)
A9: =IF(C9="","",CONCAT("JOB-",TEXT(ROW()-1,"0000"))) | P9: =N(O9)-N(N9)
A10: =IF(C10="","",CONCAT("JOB-",TEXT(ROW()-1,"0000"))) | P10: =N(O10)-N(N10)
A11: =IF(C11="","",CONCAT("JOB-",TEXT(ROW()-1,"0000"))) | P11: =N(O11)-N(N11)
A12: =IF(C12="","",CONCAT("JOB-",TEXT(ROW()-1,"0000"))) | P12: =N(O12)-N(N12)
A13: =IF(C13="","",CONCAT("JOB-",TEXT(ROW()-1,"0000"))) | P13: =N(O13)-N(N13)
... A401: =IF(C401="","",CONCAT("JOB-",TEXT(ROW()-1,"0000"))) | P401: =N(O401)-N(N401)

Sheet Estimate
A1: Field | B1: Value
A2: Estimate # | B2: =CONCAT("EST-",TEXT(ROW(),"0000"))
A3: Date
A4: Client Name
A5: Project / Service Type
A6: Site Address
A7: Phone
A8: Email
A9: Estimator
A10: Scope Summary
A11: Tax Rate (defaults from Settings) | B11: =IF(Settings!B7>0,Settings!B7,0)
A12: Deposit % (defaults from Settings) | B12: =IF(Settings!B8>0,Settings!B8,0.2)
A13: Payment Terms | B13: =Settings!B9

Sheet Estimate_Items
A1: Line # | B1: Category | C1: Item / Description | D1: Unit | E1: Qty | F1: Unit Cost | G1: Labor Hours | H1: Labor Rate | I1: Taxable? (Y/N) | J1: Line Total | L1: SUBTOTAL (All)
A2: 1 | J2: =N(E2)*N(F2) + N(G2)*N(H2) | L2: =SUM(J2:J500)
A3: 2 | J3: =N(E3)*N(F3) + N(G3)*N(H3)
A4: 3 | J4: =N(E4)*N(F4) + N(G4)*N(H4) | L4: Taxable Subtotal
A5: 4 | J5: =N(E5)*N(F5) + N(G5)*N(H5) | L5: =SUMIF(I2:I500,"Y",J2:J500)
A6: 5 | J6: =N(E6)*N(F6) + N(G6)*N(H6)
A7: 6 | J7: =N(E7)*N(F7) + N(G7)*N(H7) | L7: Tax Rate
A8: 7 | J8: =N(E8)*N(F8) + N(G8)*N(H8) | L8: =Estimate!B11
A9: 8 | J9: =N(E9)*N(F9) + N(G9)*N(H9)
A10: 9 | J10: =N(E10)*N(F10) + N(G10)*N(H10) | L10: Sales Tax
A11: 10 | J11: =N(E11)*N(F11) + N(G11)*N(H11) | L11: =N(L5)*N(L8)
A12: 11 | J12: =N(E12)*N(F12) + N(G12)*N(H12)
A13: 12 | J13: =N(E13)*N(F13) + N(G13)*N(H13) | L13: Overhead & Profit %
A14: 13 | J14: =N(E14)*N(F14) + N(G14)*N(H14) | L14: 0.1
A15: 14 | J15: =N(E15)*N(F15) + N(G15)*N(H15)
A16: 15 | J16: =N(E16)*N(F16) + N(G16)*N(H16) | L16: O&P Amount
A17: 16 | J17: =N(E17)*N(F17) + N(G17)*N(H17) | L17: =N(L2)*N(L14)
A18: 17 | J18: =N(E18)*N(F18) + N(G18)*N(H18)
A19: 18 | J19: =N(E19)*N(F19) + N(G19)*N(H19) | L19: Discount ($)
A20: 19 | J20: =N(E20)*N(F20) + N(G20)*N(H20) | L20: 0
A21: 20 | J21: =N(E21)*N(F21) + N(G21)*N(H21)
A22: 21 | J22: =N(E22)*N(F22) + N(G22)*N(H22) | L22: ESTIMATE TOTAL
A23: 22 | J23: =N(E23)*N(F23) + N(G23)*N(H23) | L23: =N(L2)+N(L11)+N(L17)-N(L20)
A24: 23 | J24: =N(E24)*N(F24) + N(G24)*N(H24)
A25: 24 | J25: =N(E25)*N(F25) + N(G25)*N(H25) | L25: Deposit %
A26: 25 | J26: =N(E26)*N(F26) + N(G26)*N(H26) | L26: =Estimate!B12
A27: 26 | J27: =N(E27)*N(F27) + N(G27)*N(H27)
A28: 27 | J28: =N(E28)*N(F28) + N(G28)*N(H28) | L28: Deposit Due
A29: 28 | J29: =N(E29)*N(F29) + N(G29)*N(H29) | L29: =N(L23)*N(L26)
A30: 29 | J30: =N(E30)*N(F30) + N(G30)*N(H30)
A31: 30 | J31: =N(E31)*N(F31) + N(G31)*N(H31) | L31: Balance Due
A32: 31 | J32: =N(E32)*N(F32) + N(G32)*N(H32) | L32: =N(L23)-N(L29)
A33: 32 | J33: =N(E33)*N(F33) + N(G33)*N(H33)
A34: 33 | J34: =N(E34)*N(F34) + N(G34)*N(H34)
A35: 34 | J35: =N(E35)*N(F35) + N(G35)*N(H35)
A36: 35 | J36: =N(E36)*N(F36) + N(G36)*N(H36)
A37: 36 | J37: =N(E37)*N(F37) + N(G37)*N(H37)
A38: 37 | J38: =N(E38)*N(F38) + N(G38)*N(H38)
A39: 38 | J39: =N(E39)*N(F39) + N(G39)*N(H39)
A40: 39 | J40: =N(E40)*N(F40) + N(G40)*N(H40)
...

Sheet Invoice
A1: Field | B1: Value
A2: Invoice # | B2: =CONCAT("INV-",TEXT(ROW(),"0000"))
A3: Date
A4: Related Estimate #
A5: Client Name
A6: Project / Service Type
A7: Site Address
A8: Phone
A9: Email
A10: Payment Method
A11: Tax Rate | B11: =IF(Settings!B7>0,Settings!B7,0)
A12: Retainage % (if any) | B12: 0.0
A13: Payment Due Terms | B13: =Settings!B9

Sheet Invoice_Items
A1: Line # | B1: Description | C1: Qty | D1: Unit | E1: Unit Price | F1: Line Total | G1: Taxable? (Y/N) | H1: Notes | J1: SUBTOTAL
A2: 1 | F2: =N(C2)*N(E2) | J2: =SUM(F2:F500)
A3: 2 | F3: =N(C3)*N(E3)
A4: 3 | F4: =N(C4)*N(E4) | J4: Taxable Subtotal
A5: 4 | F5: =N(C5)*N(E5) | J5: =SUMIF(G2:G500,"Y",F2:F500)
A6: 5 | F6: =N(C6)*N(E6)
A7: 6 | F7: =N(C7)*N(E7) | J7: Tax Rate
A8: 7 | F8: =N(C8)*N(E8) | J8: =Invoice!B10
A9: 8 | F9: =N(C9)*N(E9)
A10: 9 | F10: =N(C10)*N(E10) | J10: Sales Tax
A11: 10 | F11: =N(C11)*N(E11) | J11: =N(J5)*N(J8)
A12: 11 | F12: =N(C12)*N(E12)
A13: 12 | F13: =N(C13)*N(E13) | J13: Retainage %
A14: 13 | F14: =N(C14)*N(E14) | J14: =Invoice!B11
A15: 14 | F15: =N(C15)*N(E15)
A16: 15 | F16: =N(C16)*N(E16) | J16: Retainage Amount
A17: 16 | F17: =N(C17)*N(E17) | J17: =N(J2)*N(J14)
A18: 17 | F18: =N(C18)*N(E18)
A19: 18 | F19: =N(C19)*N(E19) | J19: INVOICE TOTAL
A20: 19 | F20: =N(C20)*N(E20) | J20: =N(J2)+N(J11)-N(J17)
A21: 20 | F21: =N(C21)*N(E21)
A22: 21 | F22: =N(C22)*N(E22) | J22: Paid to Date
A23: 22 | F23: =N(C23)*N(E23) | J23: 0
A24: 23 | F24: =N(C24)*N(E24)
A25: 24 | F25: =N(C25)*N(E25) | J25: Balance Due
A26: 25 | F26: =N(C26)*N(E26) | J26: =N(J20)-N(J23)
A27: 26 | F27: =N(C27)*N(E27)
A28: 27 | F28: =N(C28)*N(E28)
A29: 28 | F29: =N(C29)*N(E29)
A30: 29 | F30: =N(C30)*N(E30)
A31: 30 | F31: =N(C31)*N(E31)
A32: 31 | F32: =N(C32)*N(E32)
A33: 32 | F33: =N(C33)*N(E33)
A34: 33 | F34: =N(C34)*N(E34)
A35: 34 | F35: =N(C35)*N(E35)
A36: 35 | F36: =N(C36)*N(E36)
A37: 36 | F37: =N(C37)*N(E37)
A38: 37 | F38: =N(C38)*N(E38)
... A501: 500 | F501: =N(C501)*N(E501)

Sheet Change_Orders
A1: CO # | B1: Project ID | C1: Date | D1: Requested By | E1: Description | F1: Qty | G1: Unit | H1: Unit Price | I1: Labor Hours | J1: Labor Rate | K1: CO Total | L1: Approved? (Y/N) | M1: Client Signature | N1: Notes
A2: =CONCAT("CO-",TEXT(ROW()-1,"0000")) | K2: =N(F2)*N(H2) + N(I2)*N(J2)
A3: =CONCAT("CO-",TEXT(ROW()-1,"0000")) | K3: =N(F3)*N(H3) + N(I3)*N(J3)
A4: =CONCAT("CO-",TEXT(ROW()-1,"0000")) | K4: =N(F4)*N(H4) + N(I4)*N(J4)
A5: =CONCAT("CO-",TEXT(ROW()-1,"0000")) | K5: =N(F5)*N(H5) + N(I5)*N(J5)
A6: =CONCAT("CO-",TEXT(ROW()-1,"0000")) | K6: =N(F6)*N(H6) + N(I6)*N(J6)
A7: =CONCAT("CO-",TEXT(ROW()-1,"0000")) | K7: =N(F7)*N(H7) + N(I7)*N(J7)
A8: =CONCAT("CO-",TEXT(ROW()-1,"0000")) | K8: =N(F8)*N(H8) + N(I8)*N(J8)
A9: =CONCAT("CO-",TEXT(ROW()-1,"0000")) | K9: =N(F9)*N(H9) + N(I9)*N(J9)
A10: =CONCAT("CO-",TEXT(ROW()-1,"0000")) | K10: =N(F10)*N(H10) + N(I10)*N(J10)
A11: =CONCAT("CO-",TEXT(ROW()-1,"0000")) | K11: =N(F11)*N(H11) + N(I11)*N(J11)
A12: =CONCAT("CO-",TEXT(ROW()-1,"0000")) | K12: =N(F12)*N(H12) + N(I12)*N(J12)
A13: =CONCAT("CO-",TEXT(ROW()-1,"0000")) | K13: =N(F13)*N(H13) + N(I13)*N(J13)
... A401: =CONCAT("CO-",TEXT(ROW()-1,"0000")) | K401: =N(F401)*N(H401) + N(I401)*N(J401)

Sheet Job_Costing
A1: Project ID | B1: Vendor/Payee | C1: Date | D1: Category | E1: Description | F1: Qty | G1: Unit | H1: Unit Cost | I1: Labor Hours | J1: Labor Rate | K1: Line Total | L1: Receipt Link | M1: Bill/Check # | N1: Notes
K2: =N(F2)*N(H2) + N(I2)*N(J2)
K3: =N(F3)*N(H3) + N(I3)*N(J3)
K4: =N(F4)*N(H4) + N(I4)*N(J4)
K5: =N(F5)*N(H5) + N(I5)*N(J5)
K6: =N(F6)*N(H6) + N(I6)*N(J6)
K7: =N(F7)*N(H7) + N(I7)*N(J7)
K8: =N(F8)*N(H8) + N(I8)*N(J8)
K9: =N(F9)*N(H9) + N(I9)*N(J9)
K10: =N(F10)*N(H10) + N(I10)*N(J10)
K11: =N(F11)*N(H11) + N(I11)*N(J11)
K12: =N(F12)*N(H12) + N(I12)*N(J12)
K13: =N(F13)*N(H13) + N(I13)*N(J13)
... K601: =N(F601)*N(H601) + N(I601)*N(J601)

Sheet Subcontractors
A1: Subcontractor | B1: Scope | C1: Phone | D1: Email | E1: HIC License # | F1: License Exp. | G1: COI Received? (Y/N) | H1: COI Exp. | I1: W-9 on File? (Y/N) | J1: RRP Cert? (Y/N) | K1: Notes

Sheet Permits_Inspections
A1: Project ID | B1: Agency (e.g., DOB/DEP) | C1: Permit Type | D1: Application # | E1: Applied Date | F1: Issued Date | G1: Inspection Date | H1: Inspector | I1: Status | J1: Passed? (Y/N) | K1: Notes

Sheet Compliance_Checklist
A1: Item | B1: Status (Y/N) | C1: Details / Link / Date
A2: Include 3-business-day right-to-cancel clause near signature
A3: Provide two copies of Notice of Cancellation (one to keep, one to send)
A4: Show DCWP HIC license # on contract and marketing
A5: Workers' Comp certificate provided to consumer (name DCWP as certificate holder if required)
A6: Deposit / progress payments handled per NY law (escrow/bond)
A7: Start/finish dates in contract
A8: Work description and materials detailed
A9: Payment schedule and total price stated
A10: Consumer initial each page of contract (recommended)
A11: Retain signed copy of contract and any change orders

Sheet Notice_of_Cancellation
A1: NOTICE OF CANCELLATION (Consumer's Right to Cancel)
A3: Buyer Name: | D3: Contract Date:
A4: Property Address:
A5: Contractor: | D5: HIC License #:
A6: Contract #: | D6: Contract Amount:
A8: You may cancel this transaction any time before midnight of the third business day after the contract date.
A9: To cancel, sign and deliver or mail a copy of this notice to the contractor at the address listed below.
A10: If mailed, cancellation is effective when you place the notice in the mail with proper postage and address.
A12: Contractor Name & Address for Cancellation:
A14: Buyer Signature: | D14: Date:
A15: Printed Name:
A17: Second Copy for Buyer (detach and keep)

Sheet Contract_Terms
A1: Editable Contract Terms (NYC/NYS-focused)
A3: 1) Scope & Documents: This contract covers the work described in the Estimate/Proposal. Any changes require a signed Change Order. 2) Dates: Approximate start and completion dates will be stated. Delays beyond contractor’s control (weather, supply issues, inspections) may extend dates. 3) Price & Payments: Total price and payment schedule are stated. Deposits and progress payments will be handled in accordance with NY law. 4) Permits & Inspections: Contractor will obtain permits as required. Owner agrees to provide access for inspections. 5) Insurance: Contractor maintains general liability and (if applicable) workers’ compensation. Certificates available upon request. 6) Access & Site Conditions: Owner provides access to utilities and work areas; hidden conditions may require change orders. 7) Cleanup: Daily debris removal and reasonable site protection included. 8) Warranties: Workmanship warranty ___ months unless otherwise stated. Manufacturer warranties pass through to owner. 9) Right to Cancel: The owner has a right to cancel this home improvement contract within three business days after signing. A separate Notice of Cancellation is provided. 10) Dispute Resolution: Parties will attempt to resolve disputes; venue and governing law: State of New York. 11) Lien Law Notice: If subcontractors/suppliers are not paid, they may file a lien. Owner should obtain lien waivers upon payment. 12) Escrow/Trust: Where required by law, progress payments received before completion are placed in escrow or secured by a bond. 13) Signatures: Each page initialed; final page signed by owner(s) and contractor.

Sheet Field_Upload_Log
A1: Project ID | B1: Folder Link (Drive) | C1: Before Photos Link | D1: After Photos Link | E1: Uploaded By | F1: Upload Date | G1: Notes

Sheet Schedule
A1: Subject | B1: Start Date | C1: Start Time | D1: End Date | E1: End Time | F1: Location | G1: Description | H1: Project ID | I1: Client Name | J1: Type (Estimate/Job/Inspection/Payment)

Sheet README
A1: How to Use This System (Quick Start)
A3: 1) Fill out the Settings sheet with your company information (HIC #, tax rate, deposit %, payment terms). 2) Add or remove items in the list sections (Service Types, Lead Sources, etc.). These power the dropdowns throughout. 3) Enter leads in CRM_Leads. Status and service type are dropdowns. A Lead ID will auto-assign. 4) Create an estimate using Estimate + Estimate_Items. Totals calculate automatically (taxable vs non-taxable, O&P, deposit). 5) When approved, convert to a project in Project_Tracker. Link the Drive folder for photos and documents. 6) Use Job_Costing to track real costs against budget; Change_Orders to capture scope changes. 7) Use Invoice + Invoice_Items to bill the client. Retainage, sales tax, and balance due calculate automatically. 8) Permits_Inspections tracks agency info and final sign-offs. 9) Subcontractors keeps COIs, W-9s, licenses and RRP cert statuses. 10) Compliance_Checklist helps ensure NYC/NYS/FTC-required clauses (3-day cancellation) are in your contract packet. 11) Notice_of_Cancellation provides a fillable form. Print two copies—one for the buyer to keep, one to return—per NYC/DCWP best practice. 12) Schedule sheet can be exported to CSV and imported to Google Calendar (File > Download > CSV).
